{
 "cells": [
  {
   "cell_type": "code",
   "execution_count": 2,
   "metadata": {},
   "outputs": [],
   "source": [
    "import cv2\n",
    "import face_recognition"
   ]
  },
  {
   "cell_type": "code",
   "execution_count": 3,
   "metadata": {},
   "outputs": [
    {
     "name": "stdout",
     "output_type": "stream",
     "text": [
      "images/Unknown1.jpg\n"
     ]
    }
   ],
   "source": [
    "imgs = [\"images/Unknown1.jpg\"][0]\n",
    "print(imgs)\n"
   ]
  },
  {
   "cell_type": "code",
   "execution_count": 6,
   "metadata": {},
   "outputs": [],
   "source": [
    "\n",
    "# cv2 = [cv2.imread(_, 0) for _ in imgs]\n",
    "# print(type(cv2), cv2)\n",
    "cv2img = cv2.imread(imgs, 0)\n",
    "cv2img = cv2.cvtColor(cv2img, cv2.COLOR_BGR2RGB)\n",
    "# cv2.imshow('image',cv2img)\n"
   ]
  },
  {
   "cell_type": "code",
   "execution_count": 7,
   "metadata": {},
   "outputs": [
    {
     "ename": "TypeError",
     "evalue": "compute_face_descriptor(): incompatible function arguments. The following argument types are supported:\n    1. (self: _dlib_pybind11.face_recognition_model_v1, img: numpy.ndarray[(rows,cols,3),uint8], face: _dlib_pybind11.full_object_detection, num_jitters: int=0, padding: float=0.25) -> _dlib_pybind11.vector\n    2. (self: _dlib_pybind11.face_recognition_model_v1, img: numpy.ndarray[(rows,cols,3),uint8], num_jitters: int=0) -> _dlib_pybind11.vector\n    3. (self: _dlib_pybind11.face_recognition_model_v1, img: numpy.ndarray[(rows,cols,3),uint8], faces: _dlib_pybind11.full_object_detections, num_jitters: int=0, padding: float=0.25) -> _dlib_pybind11.vectors\n    4. (self: _dlib_pybind11.face_recognition_model_v1, batch_img: List[numpy.ndarray[(rows,cols,3),uint8]], batch_faces: List[_dlib_pybind11.full_object_detections], num_jitters: int=0, padding: float=0.25) -> _dlib_pybind11.vectorss\n    5. (self: _dlib_pybind11.face_recognition_model_v1, batch_img: List[numpy.ndarray[(rows,cols,3),uint8]], num_jitters: int=0) -> _dlib_pybind11.vectors\n\nInvoked with: <_dlib_pybind11.face_recognition_model_v1 object at 0x00000296E95DEFF0>, array([[37, 37, 37, ..., 37, 37, 37],\n       [37, 37, 37, ..., 37, 37, 37],\n       [37, 37, 37, ..., 37, 37, 37],\n       ...,\n       [ 0,  0,  0, ...,  0,  0,  0],\n       [ 0,  0,  0, ...,  0,  0,  0],\n       [ 0,  0,  0, ...,  0,  0,  0]], dtype=uint8), <_dlib_pybind11.full_object_detection object at 0x00000296E948F130>, 1",
     "output_type": "error",
     "traceback": [
      "\u001b[1;31m---------------------------------------------------------------------------\u001b[0m",
      "\u001b[1;31mTypeError\u001b[0m                                 Traceback (most recent call last)",
      "Cell \u001b[1;32mIn[7], line 2\u001b[0m\n\u001b[0;32m      1\u001b[0m \u001b[39m# encode = [face_recognition.face_encodings(_)[0] for _ in imgs]\u001b[39;00m\n\u001b[1;32m----> 2\u001b[0m encode \u001b[39m=\u001b[39m face_recognition\u001b[39m.\u001b[39;49mface_encodings(cv2img)[\u001b[39m0\u001b[39m]\n\u001b[0;32m      3\u001b[0m \u001b[39mprint\u001b[39m(encode)\n",
      "File \u001b[1;32mc:\\Users\\Space Exploration 3\\AppData\\Local\\Programs\\Python\\Python310\\lib\\site-packages\\face_recognition\\api.py:214\u001b[0m, in \u001b[0;36mface_encodings\u001b[1;34m(face_image, known_face_locations, num_jitters, model)\u001b[0m\n\u001b[0;32m    204\u001b[0m \u001b[39m\"\"\"\u001b[39;00m\n\u001b[0;32m    205\u001b[0m \u001b[39mGiven an image, return the 128-dimension face encoding for each face in the image.\u001b[39;00m\n\u001b[0;32m    206\u001b[0m \n\u001b[1;32m   (...)\u001b[0m\n\u001b[0;32m    211\u001b[0m \u001b[39m:return: A list of 128-dimensional face encodings (one for each face in the image)\u001b[39;00m\n\u001b[0;32m    212\u001b[0m \u001b[39m\"\"\"\u001b[39;00m\n\u001b[0;32m    213\u001b[0m raw_landmarks \u001b[39m=\u001b[39m _raw_face_landmarks(face_image, known_face_locations, model)\n\u001b[1;32m--> 214\u001b[0m \u001b[39mreturn\u001b[39;00m [np\u001b[39m.\u001b[39marray(face_encoder\u001b[39m.\u001b[39mcompute_face_descriptor(face_image, raw_landmark_set, num_jitters)) \u001b[39mfor\u001b[39;00m raw_landmark_set \u001b[39min\u001b[39;00m raw_landmarks]\n",
      "File \u001b[1;32mc:\\Users\\Space Exploration 3\\AppData\\Local\\Programs\\Python\\Python310\\lib\\site-packages\\face_recognition\\api.py:214\u001b[0m, in \u001b[0;36m<listcomp>\u001b[1;34m(.0)\u001b[0m\n\u001b[0;32m    204\u001b[0m \u001b[39m\"\"\"\u001b[39;00m\n\u001b[0;32m    205\u001b[0m \u001b[39mGiven an image, return the 128-dimension face encoding for each face in the image.\u001b[39;00m\n\u001b[0;32m    206\u001b[0m \n\u001b[1;32m   (...)\u001b[0m\n\u001b[0;32m    211\u001b[0m \u001b[39m:return: A list of 128-dimensional face encodings (one for each face in the image)\u001b[39;00m\n\u001b[0;32m    212\u001b[0m \u001b[39m\"\"\"\u001b[39;00m\n\u001b[0;32m    213\u001b[0m raw_landmarks \u001b[39m=\u001b[39m _raw_face_landmarks(face_image, known_face_locations, model)\n\u001b[1;32m--> 214\u001b[0m \u001b[39mreturn\u001b[39;00m [np\u001b[39m.\u001b[39marray(face_encoder\u001b[39m.\u001b[39;49mcompute_face_descriptor(face_image, raw_landmark_set, num_jitters)) \u001b[39mfor\u001b[39;00m raw_landmark_set \u001b[39min\u001b[39;00m raw_landmarks]\n",
      "\u001b[1;31mTypeError\u001b[0m: compute_face_descriptor(): incompatible function arguments. The following argument types are supported:\n    1. (self: _dlib_pybind11.face_recognition_model_v1, img: numpy.ndarray[(rows,cols,3),uint8], face: _dlib_pybind11.full_object_detection, num_jitters: int=0, padding: float=0.25) -> _dlib_pybind11.vector\n    2. (self: _dlib_pybind11.face_recognition_model_v1, img: numpy.ndarray[(rows,cols,3),uint8], num_jitters: int=0) -> _dlib_pybind11.vector\n    3. (self: _dlib_pybind11.face_recognition_model_v1, img: numpy.ndarray[(rows,cols,3),uint8], faces: _dlib_pybind11.full_object_detections, num_jitters: int=0, padding: float=0.25) -> _dlib_pybind11.vectors\n    4. (self: _dlib_pybind11.face_recognition_model_v1, batch_img: List[numpy.ndarray[(rows,cols,3),uint8]], batch_faces: List[_dlib_pybind11.full_object_detections], num_jitters: int=0, padding: float=0.25) -> _dlib_pybind11.vectorss\n    5. (self: _dlib_pybind11.face_recognition_model_v1, batch_img: List[numpy.ndarray[(rows,cols,3),uint8]], num_jitters: int=0) -> _dlib_pybind11.vectors\n\nInvoked with: <_dlib_pybind11.face_recognition_model_v1 object at 0x00000296E95DEFF0>, array([[37, 37, 37, ..., 37, 37, 37],\n       [37, 37, 37, ..., 37, 37, 37],\n       [37, 37, 37, ..., 37, 37, 37],\n       ...,\n       [ 0,  0,  0, ...,  0,  0,  0],\n       [ 0,  0,  0, ...,  0,  0,  0],\n       [ 0,  0,  0, ...,  0,  0,  0]], dtype=uint8), <_dlib_pybind11.full_object_detection object at 0x00000296E948F130>, 1"
     ]
    }
   ],
   "source": [
    "# encode = [face_recognition.face_encodings(_)[0] for _ in imgs]\n",
    "encode = face_recognition.face_encodings(cv2img)[0]\n",
    "print(encode)"
   ]
  }
 ],
 "metadata": {
  "kernelspec": {
   "display_name": "Python 3.10.8 64-bit",
   "language": "python",
   "name": "python3"
  },
  "language_info": {
   "codemirror_mode": {
    "name": "ipython",
    "version": 3
   },
   "file_extension": ".py",
   "mimetype": "text/x-python",
   "name": "python",
   "nbconvert_exporter": "python",
   "pygments_lexer": "ipython3",
   "version": "3.10.8"
  },
  "orig_nbformat": 4,
  "vscode": {
   "interpreter": {
    "hash": "c219292f3fd24183b3549b5d3969fdf558971f1f9390898e977007c63d46eb54"
   }
  }
 },
 "nbformat": 4,
 "nbformat_minor": 2
}
